Error message: Traceback (most recent call last):
  File "/home/damian/pepper-best-deals/env/lib/python3.9/site-packages/django/db/models/query.py", line 916, in get_or_create
    return self.get(**kwargs), False
  File "/home/damian/pepper-best-deals/env/lib/python3.9/site-packages/django/db/models/query.py", line 637, in get
    raise self.model.DoesNotExist(
pepper_app.models.UserRequest.DoesNotExist: UserRequest matching query does not exist.

During handling of the above exception, another exception occurred:

Traceback (most recent call last):
  File "/home/damian/pepper-best-deals/source/pepper_app/populate_database.py", line 21, in load_to_db
    userrequest_obj, _ = UserRequest.objects.get_or_create(
  File "/home/damian/pepper-best-deals/env/lib/python3.9/site-packages/django/db/models/manager.py", line 87, in manager_method
    return getattr(self.get_queryset(), name)(*args, **kwargs)
  File "/home/damian/pepper-best-deals/env/lib/python3.9/site-packages/django/db/models/query.py", line 923, in get_or_create
    return self.create(**params), True
  File "/home/damian/pepper-best-deals/env/lib/python3.9/site-packages/django/db/models/query.py", line 656, in create
    obj = self.model(**kwargs)
  File "/home/damian/pepper-best-deals/env/lib/python3.9/site-packages/django/db/models/base.py", line 543, in __init__
    _setattr(self, field.name, rel_obj)
  File "/home/damian/pepper-best-deals/env/lib/python3.9/site-packages/django/db/models/fields/related_descriptors.py", line 266, in __set__
    raise ValueError(
ValueError: Cannot assign "1": "UserRequest.user_id" must be a "User" instance.
, Cannot assign "1": "UserRequest.user_id" must be a "User" instance. 
