Error message: Traceback (most recent call last):
  File "/home/damian/pepper-best-deals/env/lib/python3.9/site-packages/pandas/core/indexes/base.py", line 3653, in get_loc
    return self._engine.get_loc(casted_key)
  File "pandas/_libs/index.pyx", line 147, in pandas._libs.index.IndexEngine.get_loc
  File "pandas/_libs/index.pyx", line 176, in pandas._libs.index.IndexEngine.get_loc
  File "pandas/_libs/hashtable_class_helper.pxi", line 7080, in pandas._libs.hashtable.PyObjectHashTable.get_item
  File "pandas/_libs/hashtable_class_helper.pxi", line 7088, in pandas._libs.hashtable.PyObjectHashTable.get_item
KeyError: 'article_name'

The above exception was the direct cause of the following exception:

Traceback (most recent call last):
  File "/home/damian/pepper-best-deals/source/pepper_app/populate_database.py", line 63, in load_to_db
    article_name = row["article_name"],
  File "/home/damian/pepper-best-deals/env/lib/python3.9/site-packages/pandas/core/series.py", line 1007, in __getitem__
    return self._get_value(key)
  File "/home/damian/pepper-best-deals/env/lib/python3.9/site-packages/pandas/core/series.py", line 1116, in _get_value
    loc = self.index.get_loc(label)
  File "/home/damian/pepper-best-deals/env/lib/python3.9/site-packages/pandas/core/indexes/base.py", line 3655, in get_loc
    raise KeyError(key) from err
KeyError: 'article_name'
, 'article_name' 
